<?xml version="1.0" ?><root>
<report><version>2</version><sessionid>127fe54597a6c52c67de4825</sessionid><type>desync</type><sku>ea.maxis.sims4_64.15.pc</sku><createtime>2025-03-22 13:20:57</createtime><buildsignature>Local.Unknown.Unknown.1.108.335.1020-1.300.000.188.Release</buildsignature><categoryid>venue_service.py:433</categoryid><desyncid>127fe54597a6c52c67de4825</desyncid><systemconfig/><screenshot/><desyncdata>Exception raised while processing zone spin up sequence: Multiple requests for zone directors with the same request type ZoneDirectorRequestType.DRAMA_SCHEDULER.  Original: &lt;sims4.tuning.instances.zoneDirector_University_StudentCommons_Event_Science_ExamCram object at 0x00007FF48EE06890&gt; New: &lt;sims4.tuning.instances.zoneDirector_University_StudentCommons_Event_Science_RobotBuilding object at 0x00007FF487E467D0&gt; (ValueError: Multiple requests for zone directors with the same request type ZoneDirectorRequestType.DRAMA_SCHEDULER.  Original: &lt;sims4.tuning.instances.zoneDirector_University_StudentCommons_Event_Science_ExamCram object at 0x00007FF48EE06890&gt; New: &lt;sims4.tuning.instances.zoneDirector_University_StudentCommons_Event_Science_RobotBuilding object at 0x00007FF487E467D0&gt;)&#13;&#10;Traceback (most recent call last):&#13;&#10;&#13;&#10;  File "T:\InGame\Gameplay\Scripts\Server\areaserver.py", line 130, in wrapped&#13;&#10;  File "T:\InGame\Gameplay\Scripts\Server\areaserver.py", line 126, in finally_wrap&#13;&#10;  File "T:\InGame\Gameplay\Scripts\Core\sims4\utils.py", line 157, in wrapper&#13;&#10;  File "T:\InGame\Gameplay\Scripts\Core\sims4\utils.py", line 175, in wrapper&#13;&#10;  File "T:\InGame\Gameplay\Scripts\Server\areaserver.py", line 383, in c_api_client_connect&#13;&#10;  File "T:\InGame\Gameplay\Scripts\Server\zone.py", line 609, in do_zone_spin_up&#13;&#10;  File "T:\InGame\Gameplay\Scripts\Server\zone_spin_up_service.py", line 1682, in update&#13;&#10;  File "T:\InGame\Gameplay\Scripts\Server\zone_spin_up_service.py", line 394, in on_enter&#13;&#10;  File "T:\InGame\Gameplay\Scripts\Server\drama_scheduler\drama_scheduler.py", line 1112, in make_zone_director_requests&#13;&#10;  File "T:\InGame\Gameplay\Scripts\Server\venues\venue_service.py", line 433, in request_zone_director&#13;&#10;ValueError: Multiple requests for zone directors with the same request type ZoneDirectorRequestType.DRAMA_SCHEDULER.  Original: &lt;sims4.tuning.instances.zoneDirector_University_StudentCommons_Event_Science_ExamCram object at 0x00007FF48EE06890&gt; New: &lt;sims4.tuning.instances.zoneDirector_University_StudentCommons_Event_Science_RobotBuilding object at 0x00007FF487E467D0&gt;rtim=0&#13;&#10;Client Session Time: 42.68&#13; &#10;Num Save Errors: 0&#13; &#10;Num Load Errors: 0&#13; &#10;Current Game State: 0xdd4141d5&#13; &#10;LoadingScreenActiveFlag: 1&#13; &#10;Origin Version: 12,168,0,5425&#13; &#10;Modded: True&#13; &#10;SystemInfo: Windows 10 10.0.19045 GPU: NVIDIA GeForce GTX 1080 nvldumdx.dll 32.0.15.7260, GUID: D7B71E3E-58C0-11CF-B46B-0D170EC2ED35&#13; &#10;</desyncdata></report>
<report><version>2</version><sessionid>127fe54597a6c52c67de4825</sessionid><type>desync</type><sku>ea.maxis.sims4_64.15.pc</sku><createtime>2025-03-22 14:47:31</createtime><buildsignature>Local.Unknown.Unknown.1.108.335.1020-1.300.000.188.Release</buildsignature><categoryid>cpp_message.py:107</categoryid><desyncid>127fe54597a6c52c67de4825</desyncid><systemconfig/><screenshot/><desyncdata>Exception occurred while attempting to populate a repeated field: (ValueError: Value out of range: 11972089895127609288570)&#13;&#10;Traceback (most recent call last):&#13;&#10;&#13;&#10;  File "T:\InGame\Gameplay\Scripts\Core\sims4\utils.py", line 179, in wrapper&#13;&#10;  File "T:\InGame\Gameplay\Scripts\Server\areaserver.py", line 219, in c_api_server_tick&#13;&#10;  File "T:\InGame\Gameplay\Scripts\Server\scheduling.py", line 231, in simulate&#13;&#10;  File "T:\InGame\Gameplay\Scripts\Server\elements.py", line 376, in _run&#13;&#10;  File "T:\InGame\Gameplay\Scripts\Server\services\persistence_service.py", line 452, in call_save_game_gen&#13;&#10;  File "T:\InGame\Gameplay\Scripts\Server\services\persistence_service.py", line 486, in save_game_gen&#13;&#10;  File "T:\InGame\Gameplay\Scripts\Server\services\persistence_service.py", line 529, in _save_game_gen&#13;&#10;  File "T:\InGame\Gameplay\Scripts\Server\services\persistence_service.py", line 598, in _fill_and_send_save_game_protobufs_gen&#13;&#10;  File "T:\InGame\Gameplay\Scripts\Core\sims4\service_manager.py", line 537, in save_all_services&#13;&#10;  File "T:\InGame\Gameplay\Scripts\Server\zone_manager.py", line 120, in save&#13;&#10;  File "T:\InGame\Gameplay\Scripts\Server\zone.py", line 1758, in save_zone&#13;&#10;  File "T:\InGame\Gameplay\Scripts\Server\game_services.py", line 50, in save_all_services&#13;&#10;  File "T:\InGame\Gameplay\Scripts\Core\sims4\service_manager.py", line 537, in save_all_services&#13;&#10;  File "T:\InGame\Gameplay\Scripts\Server\organizations\organization_service.py", line 152, in save&#13;&#10;  File "T:\InGame\Gameplay\Scripts\Core\google\protobuf\internal\cpp_message.py", line 107, in Setter&#13;&#10;ValueError: Value out of range: 11972089895127609288570rtim=0&#13;&#10;Client Session Time: 42.68&#13; &#10;Num Save Errors: 0&#13; &#10;Num Load Errors: 0&#13; &#10;Current Game State: 0xdd4141d5&#13; &#10;LoadingScreenActiveFlag: 1&#13; &#10;Origin Version: 12,168,0,5425&#13; &#10;Modded: True&#13; &#10;SystemInfo: Windows 10 10.0.19045 GPU: NVIDIA GeForce GTX 1080 nvldumdx.dll 32.0.15.7260, GUID: D7B71E3E-58C0-11CF-B46B-0D170EC2ED35&#13; &#10;</desyncdata></report>
<report><version>2</version><sessionid>127fe54597a6c52c67de4825</sessionid><type>desync</type><sku>ea.maxis.sims4_64.15.pc</sku><createtime>2025-03-22 14:47:31</createtime><buildsignature>Local.Unknown.Unknown.1.108.335.1020-1.300.000.188.Release</buildsignature><categoryid>cpp_message.py:107</categoryid><desyncid>127fe54597a6c52c67de4825</desyncid><systemconfig/><screenshot/><desyncdata>Exception occurred while attempting to populate a repeated field: (ValueError: Value out of range: 11972089895127609288570)&#13;&#10;Traceback (most recent call last):&#13;&#10;&#13;&#10;  File "T:\InGame\Gameplay\Scripts\Core\sims4\utils.py", line 179, in wrapper&#13;&#10;  File "T:\InGame\Gameplay\Scripts\Server\areaserver.py", line 219, in c_api_server_tick&#13;&#10;  File "T:\InGame\Gameplay\Scripts\Server\scheduling.py", line 231, in simulate&#13;&#10;  File "T:\InGame\Gameplay\Scripts\Server\elements.py", line 376, in _run&#13;&#10;  File "T:\InGame\Gameplay\Scripts\Server\services\persistence_service.py", line 452, in call_save_game_gen&#13;&#10;  File "T:\InGame\Gameplay\Scripts\Server\services\persistence_service.py", line 486, in save_game_gen&#13;&#10;  File "T:\InGame\Gameplay\Scripts\Server\services\persistence_service.py", line 529, in _save_game_gen&#13;&#10;  File "T:\InGame\Gameplay\Scripts\Server\services\persistence_service.py", line 598, in _fill_and_send_save_game_protobufs_gen&#13;&#10;  File "T:\InGame\Gameplay\Scripts\Core\sims4\service_manager.py", line 537, in save_all_services&#13;&#10;  File "T:\InGame\Gameplay\Scripts\Server\zone_manager.py", line 120, in save&#13;&#10;  File "T:\InGame\Gameplay\Scripts\Server\zone.py", line 1758, in save_zone&#13;&#10;  File "T:\InGame\Gameplay\Scripts\Server\game_services.py", line 50, in save_all_services&#13;&#10;  File "T:\InGame\Gameplay\Scripts\Core\sims4\service_manager.py", line 537, in save_all_services&#13;&#10;  File "T:\InGame\Gameplay\Scripts\Server\organizations\organization_service.py", line 152, in save&#13;&#10;  File "T:\InGame\Gameplay\Scripts\Core\google\protobuf\internal\cpp_message.py", line 107, in Setter&#13;&#10;ValueError: Value out of range: 11972089895127609288570rtim=0&#13;&#10;Client Session Time: 42.68&#13; &#10;Num Save Errors: 0&#13; &#10;Num Load Errors: 0&#13; &#10;Current Game State: 0xdd4141d5&#13; &#10;LoadingScreenActiveFlag: 1&#13; &#10;Origin Version: 12,168,0,5425&#13; &#10;Modded: True&#13; &#10;SystemInfo: Windows 10 10.0.19045 GPU: NVIDIA GeForce GTX 1080 nvldumdx.dll 32.0.15.7260, GUID: D7B71E3E-58C0-11CF-B46B-0D170EC2ED35&#13; &#10;</desyncdata></report>
<report><version>2</version><sessionid>127fe54597a6c52c67de4825</sessionid><type>desync</type><sku>ea.maxis.sims4_64.15.pc</sku><createtime>2025-03-22 14:51:17</createtime><buildsignature>Local.Unknown.Unknown.1.108.335.1020-1.300.000.188.Release</buildsignature><categoryid>cpp_message.py:107</categoryid><desyncid>127fe54597a6c52c67de4825</desyncid><systemconfig/><screenshot/><desyncdata>Exception occurred while attempting to populate a repeated field: (ValueError: Value out of range: 11972089895127609042867)&#13;&#10;Traceback (most recent call last):&#13;&#10;&#13;&#10;  File "T:\InGame\Gameplay\Scripts\Core\sims4\utils.py", line 179, in wrapper&#13;&#10;  File "T:\InGame\Gameplay\Scripts\Server\areaserver.py", line 219, in c_api_server_tick&#13;&#10;  File "T:\InGame\Gameplay\Scripts\Server\scheduling.py", line 231, in simulate&#13;&#10;  File "T:\InGame\Gameplay\Scripts\Server\elements.py", line 376, in _run&#13;&#10;  File "T:\InGame\Gameplay\Scripts\Server\services\persistence_service.py", line 452, in call_save_game_gen&#13;&#10;  File "T:\InGame\Gameplay\Scripts\Server\services\persistence_service.py", line 486, in save_game_gen&#13;&#10;  File "T:\InGame\Gameplay\Scripts\Server\services\persistence_service.py", line 529, in _save_game_gen&#13;&#10;  File "T:\InGame\Gameplay\Scripts\Server\services\persistence_service.py", line 598, in _fill_and_send_save_game_protobufs_gen&#13;&#10;  File "T:\InGame\Gameplay\Scripts\Core\sims4\service_manager.py", line 537, in save_all_services&#13;&#10;  File "T:\InGame\Gameplay\Scripts\Server\zone_manager.py", line 120, in save&#13;&#10;  File "T:\InGame\Gameplay\Scripts\Server\zone.py", line 1758, in save_zone&#13;&#10;  File "T:\InGame\Gameplay\Scripts\Server\game_services.py", line 50, in save_all_services&#13;&#10;  File "T:\InGame\Gameplay\Scripts\Core\sims4\service_manager.py", line 537, in save_all_services&#13;&#10;  File "T:\InGame\Gameplay\Scripts\Server\organizations\organization_service.py", line 152, in save&#13;&#10;  File "T:\InGame\Gameplay\Scripts\Core\google\protobuf\internal\cpp_message.py", line 107, in Setter&#13;&#10;ValueError: Value out of range: 11972089895127609042867rtim=0&#13;&#10;Client Session Time: 42.68&#13; &#10;Num Save Errors: 0&#13; &#10;Num Load Errors: 0&#13; &#10;Current Game State: 0xdd4141d5&#13; &#10;LoadingScreenActiveFlag: 1&#13; &#10;Origin Version: 12,168,0,5425&#13; &#10;Modded: True&#13; &#10;SystemInfo: Windows 10 10.0.19045 GPU: NVIDIA GeForce GTX 1080 nvldumdx.dll 32.0.15.7260, GUID: D7B71E3E-58C0-11CF-B46B-0D170EC2ED35&#13; &#10;</desyncdata></report>
<report><version>2</version><sessionid>127fe54597a6c52c67de4825</sessionid><type>desync</type><sku>ea.maxis.sims4_64.15.pc</sku><createtime>2025-03-22 14:51:17</createtime><buildsignature>Local.Unknown.Unknown.1.108.335.1020-1.300.000.188.Release</buildsignature><categoryid>cpp_message.py:107</categoryid><desyncid>127fe54597a6c52c67de4825</desyncid><systemconfig/><screenshot/><desyncdata>Exception occurred while attempting to populate a repeated field: (ValueError: Value out of range: 11972089895127609042867)&#13;&#10;Traceback (most recent call last):&#13;&#10;&#13;&#10;  File "T:\InGame\Gameplay\Scripts\Core\sims4\utils.py", line 179, in wrapper&#13;&#10;  File "T:\InGame\Gameplay\Scripts\Server\areaserver.py", line 219, in c_api_server_tick&#13;&#10;  File "T:\InGame\Gameplay\Scripts\Server\scheduling.py", line 231, in simulate&#13;&#10;  File "T:\InGame\Gameplay\Scripts\Server\elements.py", line 376, in _run&#13;&#10;  File "T:\InGame\Gameplay\Scripts\Server\services\persistence_service.py", line 452, in call_save_game_gen&#13;&#10;  File "T:\InGame\Gameplay\Scripts\Server\services\persistence_service.py", line 486, in save_game_gen&#13;&#10;  File "T:\InGame\Gameplay\Scripts\Server\services\persistence_service.py", line 529, in _save_game_gen&#13;&#10;  File "T:\InGame\Gameplay\Scripts\Server\services\persistence_service.py", line 598, in _fill_and_send_save_game_protobufs_gen&#13;&#10;  File "T:\InGame\Gameplay\Scripts\Core\sims4\service_manager.py", line 537, in save_all_services&#13;&#10;  File "T:\InGame\Gameplay\Scripts\Server\zone_manager.py", line 120, in save&#13;&#10;  File "T:\InGame\Gameplay\Scripts\Server\zone.py", line 1758, in save_zone&#13;&#10;  File "T:\InGame\Gameplay\Scripts\Server\game_services.py", line 50, in save_all_services&#13;&#10;  File "T:\InGame\Gameplay\Scripts\Core\sims4\service_manager.py", line 537, in save_all_services&#13;&#10;  File "T:\InGame\Gameplay\Scripts\Server\organizations\organization_service.py", line 152, in save&#13;&#10;  File "T:\InGame\Gameplay\Scripts\Core\google\protobuf\internal\cpp_message.py", line 107, in Setter&#13;&#10;ValueError: Value out of range: 11972089895127609042867rtim=0&#13;&#10;Client Session Time: 42.68&#13; &#10;Num Save Errors: 0&#13; &#10;Num Load Errors: 0&#13; &#10;Current Game State: 0xdd4141d5&#13; &#10;LoadingScreenActiveFlag: 1&#13; &#10;Origin Version: 12,168,0,5425&#13; &#10;Modded: True&#13; &#10;SystemInfo: Windows 10 10.0.19045 GPU: NVIDIA GeForce GTX 1080 nvldumdx.dll 32.0.15.7260, GUID: D7B71E3E-58C0-11CF-B46B-0D170EC2ED35&#13; &#10;</desyncdata></report>
<report><version>2</version><sessionid>127fe54597a6c52c67de4825</sessionid><type>desync</type><sku>ea.maxis.sims4_64.15.pc</sku><createtime>2025-03-22 14:51:22</createtime><buildsignature>Local.Unknown.Unknown.1.108.335.1020-1.300.000.188.Release</buildsignature><categoryid>cpp_message.py:107</categoryid><desyncid>127fe54597a6c52c67de4825</desyncid><systemconfig/><screenshot/><desyncdata>Exception occurred while attempting to populate a repeated field: (ValueError: Value out of range: 11972089895127609032916)&#13;&#10;Traceback (most recent call last):&#13;&#10;&#13;&#10;  File "T:\InGame\Gameplay\Scripts\Core\sims4\utils.py", line 179, in wrapper&#13;&#10;  File "T:\InGame\Gameplay\Scripts\Server\areaserver.py", line 219, in c_api_server_tick&#13;&#10;  File "T:\InGame\Gameplay\Scripts\Server\scheduling.py", line 231, in simulate&#13;&#10;  File "T:\InGame\Gameplay\Scripts\Server\elements.py", line 376, in _run&#13;&#10;  File "T:\InGame\Gameplay\Scripts\Server\services\persistence_service.py", line 452, in call_save_game_gen&#13;&#10;  File "T:\InGame\Gameplay\Scripts\Server\areaserver.py", line 452, in request_client_disconnect_gen&#13;&#10;  File "T:\InGame\Gameplay\Scripts\Server\services\persistence_service.py", line 468, in save_to_scratch_slot_gen&#13;&#10;  File "T:\InGame\Gameplay\Scripts\Server\services\persistence_service.py", line 486, in save_game_gen&#13;&#10;  File "T:\InGame\Gameplay\Scripts\Server\services\persistence_service.py", line 529, in _save_game_gen&#13;&#10;  File "T:\InGame\Gameplay\Scripts\Server\services\persistence_service.py", line 598, in _fill_and_send_save_game_protobufs_gen&#13;&#10;  File "T:\InGame\Gameplay\Scripts\Core\sims4\service_manager.py", line 537, in save_all_services&#13;&#10;  File "T:\InGame\Gameplay\Scripts\Server\zone_manager.py", line 120, in save&#13;&#10;  File "T:\InGame\Gameplay\Scripts\Server\zone.py", line 1758, in save_zone&#13;&#10;  File "T:\InGame\Gameplay\Scripts\Server\game_services.py", line 50, in save_all_services&#13;&#10;  File "T:\InGame\Gameplay\Scripts\Core\sims4\service_manager.py", line 537, in save_all_services&#13;&#10;  File "T:\InGame\Gameplay\Scripts\Server\organizations\organization_service.py", line 152, in save&#13;&#10;  File "T:\InGame\Gameplay\Scripts\Core\google\protobuf\internal\cpp_message.py", line 107, in Setter&#13;&#10;ValueError: Value out of range: 11972089895127609032916rtim=0&#13;&#10;Client Session Time: 42.68&#13; &#10;Num Save Errors: 0&#13; &#10;Num Load Errors: 0&#13; &#10;Current Game State: 0xdd4141d5&#13; &#10;LoadingScreenActiveFlag: 1&#13; &#10;Origin Version: 12,168,0,5425&#13; &#10;Modded: True&#13; &#10;SystemInfo: Windows 10 10.0.19045 GPU: NVIDIA GeForce GTX 1080 nvldumdx.dll 32.0.15.7260, GUID: D7B71E3E-58C0-11CF-B46B-0D170EC2ED35&#13; &#10;</desyncdata></report>
<report><version>2</version><sessionid>127fe54597a6c52c67de4825</sessionid><type>desync</type><sku>ea.maxis.sims4_64.15.pc</sku><createtime>2025-03-22 14:51:22</createtime><buildsignature>Local.Unknown.Unknown.1.108.335.1020-1.300.000.188.Release</buildsignature><categoryid>cpp_message.py:107</categoryid><desyncid>127fe54597a6c52c67de4825</desyncid><systemconfig/><screenshot/><desyncdata>Exception occurred while attempting to populate a repeated field: (ValueError: Value out of range: 11972089895127609032916)&#13;&#10;Traceback (most recent call last):&#13;&#10;&#13;&#10;  File "T:\InGame\Gameplay\Scripts\Core\sims4\utils.py", line 179, in wrapper&#13;&#10;  File "T:\InGame\Gameplay\Scripts\Server\areaserver.py", line 219, in c_api_server_tick&#13;&#10;  File "T:\InGame\Gameplay\Scripts\Server\scheduling.py", line 231, in simulate&#13;&#10;  File "T:\InGame\Gameplay\Scripts\Server\elements.py", line 376, in _run&#13;&#10;  File "T:\InGame\Gameplay\Scripts\Server\services\persistence_service.py", line 452, in call_save_game_gen&#13;&#10;  File "T:\InGame\Gameplay\Scripts\Server\areaserver.py", line 452, in request_client_disconnect_gen&#13;&#10;  File "T:\InGame\Gameplay\Scripts\Server\services\persistence_service.py", line 468, in save_to_scratch_slot_gen&#13;&#10;  File "T:\InGame\Gameplay\Scripts\Server\services\persistence_service.py", line 486, in save_game_gen&#13;&#10;  File "T:\InGame\Gameplay\Scripts\Server\services\persistence_service.py", line 529, in _save_game_gen&#13;&#10;  File "T:\InGame\Gameplay\Scripts\Server\services\persistence_service.py", line 598, in _fill_and_send_save_game_protobufs_gen&#13;&#10;  File "T:\InGame\Gameplay\Scripts\Core\sims4\service_manager.py", line 537, in save_all_services&#13;&#10;  File "T:\InGame\Gameplay\Scripts\Server\zone_manager.py", line 120, in save&#13;&#10;  File "T:\InGame\Gameplay\Scripts\Server\zone.py", line 1758, in save_zone&#13;&#10;  File "T:\InGame\Gameplay\Scripts\Server\game_services.py", line 50, in save_all_services&#13;&#10;  File "T:\InGame\Gameplay\Scripts\Core\sims4\service_manager.py", line 537, in save_all_services&#13;&#10;  File "T:\InGame\Gameplay\Scripts\Server\organizations\organization_service.py", line 152, in save&#13;&#10;  File "T:\InGame\Gameplay\Scripts\Core\google\protobuf\internal\cpp_message.py", line 107, in Setter&#13;&#10;ValueError: Value out of range: 11972089895127609032916rtim=0&#13;&#10;Client Session Time: 42.68&#13; &#10;Num Save Errors: 0&#13; &#10;Num Load Errors: 0&#13; &#10;Current Game State: 0xdd4141d5&#13; &#10;LoadingScreenActiveFlag: 1&#13; &#10;Origin Version: 12,168,0,5425&#13; &#10;Modded: True&#13; &#10;SystemInfo: Windows 10 10.0.19045 GPU: NVIDIA GeForce GTX 1080 nvldumdx.dll 32.0.15.7260, GUID: D7B71E3E-58C0-11CF-B46B-0D170EC2ED35&#13; &#10;</desyncdata></report>
<report><version>2</version><sessionid>127fe54597a6c52c67de4825</sessionid><type>desync</type><sku>ea.maxis.sims4_64.15.pc</sku><createtime>2025-03-22 15:01:25</createtime><buildsignature>Local.Unknown.Unknown.1.108.335.1020-1.300.000.188.Release</buildsignature><categoryid>posture_graph.py:5164</categoryid><desyncid>127fe54597a6c52c67de4825</desyncid><systemconfig/><screenshot/><desyncdata>[rez] Posture graph threw an exception while being queried by autonomy: (AssertionError: Source spec not in the posture graph: stand@object_paintEaselGEN_01:0x0fe4042667a30000, carry, surface:slot_target@object_paintEaselGEN_01:0x0fe4042667a30000 for interaction:  running canvas_PaintPainting_Staging_Small:75998 on object_Canvas_small:0x0a641460e80b57f0  (guaranteed))&#13;&#10;Traceback (most recent call last):&#13;&#10;Caught and logged:&#13;&#10;&#13;&#10;  File "T:\InGame\Gameplay\Scripts\Server\postures\transition_sequence.py", line 2988, in _get_transitions_for_sim&#13;&#10;  File "postures\posture_graph.py", line 5164, in postures.posture_graph.PostureGraphService.get_segmented_paths&#13;&#10;AssertionError: Source spec not in the posture graph: stand@object_paintEaselGEN_01:0x0fe4042667a30000, carry, surface:slot_target@object_paintEaselGEN_01:0x0fe4042667a30000 for interaction:  running canvas_PaintPainting_Staging_Small:75998 on object_Canvas_small:0x0a641460e80b57f0  (guaranteed)rtim=0&#13;&#10;Client Session Time: 42.68&#13; &#10;Num Save Errors: 0&#13; &#10;Num Load Errors: 0&#13; &#10;Current Game State: 0xdd4141d5&#13; &#10;LoadingScreenActiveFlag: 1&#13; &#10;Origin Version: 12,168,0,5425&#13; &#10;Modded: True&#13; &#10;SystemInfo: Windows 10 10.0.19045 GPU: NVIDIA GeForce GTX 1080 nvldumdx.dll 32.0.15.7260, GUID: D7B71E3E-58C0-11CF-B46B-0D170EC2ED35&#13; &#10;</desyncdata></report>
</root>